2024-07-21 01:12:30.958 | INFO     | utils.utils:info:59 - [TikTok][o6_.7260] Cannot find Room ID.
2024-07-21 01:12:31.427 | INFO     | utils.utils:info:59 - [TikTok][o6_.7260] room_id not found
2024-07-21 01:12:31.427 | INFO     | utils.utils:info:59 - Waiting 10 seconds
2024-07-21 01:12:43.877 | INFO     | utils.utils:info:59 - [TikTok][o6_.7260] Cannot find Room ID.
2024-07-21 01:12:46.442 | INFO     | utils.utils:info:59 - [TikTok][o6_.7260] room_id not found
2024-07-21 01:12:46.442 | INFO     | utils.utils:info:59 - Waiting 10 seconds
2024-07-21 01:12:56.809 | ERROR    | utils.utils:error:67 - [TikTok][o6_.7260] Exception occurred: ('Connection aborted.', ConnectionResetError(10054, '현재 연결은 원격 호스트에 의해 강제로 끊겼습니다', None, 10054, None))
--- Logging error in Loguru Handler #1 ---
Record was: {'elapsed': datetime.timedelta(days=2, seconds=9342, microseconds=985367), 'exception': None, 'extra': {}, 'file': (name='utils.py', path='utils\\utils.py'), 'function': 'error', 'level': (name='ERROR', no=40, icon='❌'), 'line': 67, 'message': "[TikTok][o6_.7260] Exception occurred: ('Connection aborted.', ConnectionResetError(10054, '현재 연결은 원격 호스트에 의해 강제로 끊겼습니다', None, 10054, None))", 'module': 'utils', 'name': 'utils.utils', 'process': (id=14152, name='MainProcess'), 'thread': (id=14144, name='MainThread'), 'time': datetime(2024, 7, 21, 1, 12, 56, 809461, tzinfo=datetime.timezone(datetime.timedelta(seconds=32400), '대한민국 표준시'))}
Traceback (most recent call last):
  File "urllib3\connectionpool.py", line 789, in urlopen
  File "urllib3\connectionpool.py", line 490, in _make_request
  File "urllib3\connectionpool.py", line 466, in _make_request
  File "urllib3\connectionpool.py", line 1095, in _validate_conn
  File "urllib3\connection.py", line 652, in connect
  File "urllib3\connection.py", line 805, in _ssl_wrap_socket_and_match_hostname
  File "urllib3\util\ssl_.py", line 465, in ssl_wrap_socket
  File "urllib3\util\ssl_.py", line 509, in _ssl_wrap_socket_impl
  File "ssl.py", line 455, in wrap_socket
  File "ssl.py", line 1042, in _create
  File "ssl.py", line 1320, in do_handshake
ConnectionResetError: [WinError 10054] 현재 연결은 원격 호스트에 의해 강제로 끊겼습니다

During handling of the above exception, another exception occurred:

Traceback (most recent call last):
  File "requests\adapters.py", line 667, in send
  File "urllib3\connectionpool.py", line 843, in urlopen
  File "urllib3\util\retry.py", line 474, in increment
  File "urllib3\util\util.py", line 38, in reraise
  File "urllib3\connectionpool.py", line 789, in urlopen
  File "urllib3\connectionpool.py", line 490, in _make_request
  File "urllib3\connectionpool.py", line 466, in _make_request
  File "urllib3\connectionpool.py", line 1095, in _validate_conn
  File "urllib3\connection.py", line 652, in connect
  File "urllib3\connection.py", line 805, in _ssl_wrap_socket_and_match_hostname
  File "urllib3\util\ssl_.py", line 465, in ssl_wrap_socket
  File "urllib3\util\ssl_.py", line 509, in _ssl_wrap_socket_impl
  File "ssl.py", line 455, in wrap_socket
  File "ssl.py", line 1042, in _create
  File "ssl.py", line 1320, in do_handshake
urllib3.exceptions.ProtocolError: ('Connection aborted.', ConnectionResetError(10054, '현재 연결은 원격 호스트에 의해 강제로 끊겼습니다', None, 10054, None))

During handling of the above exception, another exception occurred:

Traceback (most recent call last):
  File "recorders\recorders.py", line 318, in test_get_room_id_from_user
  File "requests\api.py", line 73, in get
  File "requests\api.py", line 59, in request
  File "requests\sessions.py", line 589, in request
  File "requests\sessions.py", line 703, in send
  File "requests\adapters.py", line 682, in send
requests.exceptions.ConnectionError: ('Connection aborted.', ConnectionResetError(10054, '현재 연결은 원격 호스트에 의해 강제로 끊겼습니다', None, 10054, None))

During handling of the above exception, another exception occurred:

Traceback (most recent call last):
  File "loguru\_handler.py", line 206, in emit
  File "loguru\_file_sink.py", line 204, in write
  File "loguru\_file_sink.py", line 290, in _terminate_file
  File "loguru\_file_sink.py", line 84, in retention_age
PermissionError: [WinError 32] 다른 프로세스가 파일을 사용 중이기 때문에 프로세스가 액세스 할 수 없습니다: 'logs\\log_2024-07-17.log'
--- End of logging error ---
2024-07-21 01:12:56.825 | ERROR    | utils.utils:error:67 - Exception caught in main:
2024-07-21 01:12:56.825 | ERROR    | utils.utils:error:67 - ('Connection aborted.', ConnectionResetError(10054, '현재 연결은 원격 호스트에 의해 강제로 끊겼습니다', None, 10054, None))

Traceback (most recent call last):
  File "urllib3\connectionpool.py", line 789, in urlopen
  File "urllib3\connectionpool.py", line 490, in _make_request
  File "urllib3\connectionpool.py", line 466, in _make_request
  File "urllib3\connectionpool.py", line 1095, in _validate_conn
  File "urllib3\connection.py", line 652, in connect
  File "urllib3\connection.py", line 805, in _ssl_wrap_socket_and_match_hostname
  File "urllib3\util\ssl_.py", line 465, in ssl_wrap_socket
  File "urllib3\util\ssl_.py", line 509, in _ssl_wrap_socket_impl
  File "ssl.py", line 455, in wrap_socket
  File "ssl.py", line 1042, in _create
  File "ssl.py", line 1320, in do_handshake
ConnectionResetError: [WinError 10054] 현재 연결은 원격 호스트에 의해 강제로 끊겼습니다

During handling of the above exception, another exception occurred:

Traceback (most recent call last):
  File "requests\adapters.py", line 667, in send
  File "urllib3\connectionpool.py", line 843, in urlopen
  File "urllib3\util\retry.py", line 474, in increment
  File "urllib3\util\util.py", line 38, in reraise
  File "urllib3\connectionpool.py", line 789, in urlopen
  File "urllib3\connectionpool.py", line 490, in _make_request
  File "urllib3\connectionpool.py", line 466, in _make_request
  File "urllib3\connectionpool.py", line 1095, in _validate_conn
  File "urllib3\connection.py", line 652, in connect
  File "urllib3\connection.py", line 805, in _ssl_wrap_socket_and_match_hostname
  File "urllib3\util\ssl_.py", line 465, in ssl_wrap_socket
  File "urllib3\util\ssl_.py", line 509, in _ssl_wrap_socket_impl
  File "ssl.py", line 455, in wrap_socket
  File "ssl.py", line 1042, in _create
  File "ssl.py", line 1320, in do_handshake
urllib3.exceptions.ProtocolError: ('Connection aborted.', ConnectionResetError(10054, '현재 연결은 원격 호스트에 의해 강제로 끊겼습니다', None, 10054, None))

During handling of the above exception, another exception occurred:

Traceback (most recent call last):
  File "main.py", line 12, in main
  File "recorders\recorders.py", line 66, in run
  File "recorders\recorders.py", line 386, in test_get_room_id_from_user
  File "recorders\recorders.py", line 318, in test_get_room_id_from_user
  File "requests\api.py", line 73, in get
  File "requests\api.py", line 59, in request
  File "requests\sessions.py", line 589, in request
  File "requests\sessions.py", line 703, in send
  File "requests\adapters.py", line 682, in send
requests.exceptions.ConnectionError: ('Connection aborted.', ConnectionResetError(10054, '현재 연결은 원격 호스트에 의해 강제로 끊겼습니다', None, 10054, None))