2024-08-08 23:57:45.819 | ERROR    | recorders.recorders:request:81 - [Afreeca][jeehyeoun] HTTP error: All connection attempts failed
--- Logging error in Loguru Handler #1 ---
Record was: {'elapsed': datetime.timedelta(days=4, seconds=42907, microseconds=894424), 'exception': None, 'extra': {}, 'file': (name='recorders.py', path='recorders\\recorders.py'), 'function': 'request', 'level': (name='ERROR', no=40, icon='❌'), 'line': 81, 'message': '[Afreeca][jeehyeoun] HTTP error: All connection attempts failed', 'module': 'recorders', 'name': 'recorders.recorders', 'process': (id=11740, name='MainProcess'), 'thread': (id=8400, name='MainThread'), 'time': datetime(2024, 8, 8, 23, 57, 45, 819485, tzinfo=datetime.timezone(datetime.timedelta(seconds=32400), '대한민국 표준시'))}
Traceback (most recent call last):
  File "httpx\_transports\default.py", line 69, in map_httpcore_exceptions
  File "httpx\_transports\default.py", line 373, in handle_async_request
  File "httpcore\_async\connection_pool.py", line 216, in handle_async_request
  File "httpcore\_async\connection_pool.py", line 196, in handle_async_request
  File "httpcore\_async\connection.py", line 99, in handle_async_request
  File "httpcore\_async\connection.py", line 76, in handle_async_request
  File "httpcore\_async\connection.py", line 122, in _connect
  File "httpcore\_backends\auto.py", line 30, in connect_tcp
  File "httpcore\_backends\anyio.py", line 114, in connect_tcp
  File "contextlib.py", line 158, in __exit__
  File "httpcore\_exceptions.py", line 14, in map_exceptions
httpcore.ConnectError: All connection attempts failed

The above exception was the direct cause of the following exception:

Traceback (most recent call last):
  File "recorders\recorders.py", line 75, in request
  File "httpx\_client.py", line 1574, in request
  File "httpx\_client.py", line 1661, in send
  File "httpx\_client.py", line 1689, in _send_handling_auth
  File "httpx\_client.py", line 1726, in _send_handling_redirects
  File "httpx\_client.py", line 1763, in _send_single_request
  File "httpx\_transports\default.py", line 372, in handle_async_request
  File "contextlib.py", line 158, in __exit__
  File "httpx\_transports\default.py", line 86, in map_httpcore_exceptions
httpx.ConnectError: All connection attempts failed

During handling of the above exception, another exception occurred:

Traceback (most recent call last):
  File "loguru\_handler.py", line 206, in emit
  File "loguru\_file_sink.py", line 204, in write
  File "loguru\_file_sink.py", line 290, in _terminate_file
  File "loguru\_file_sink.py", line 84, in retention_age
PermissionError: [WinError 32] 다른 프로세스가 파일을 사용 중이기 때문에 프로세스가 액세스 할 수 없습니다: 'logs\\log_2024-08-02.log'
--- End of logging error ---
2024-08-08 23:57:45.834 | ERROR    | recorders.recorders:start:58 - [Afreeca][jeehyeoun] All connection attempts failed
2024-08-10 00:12:45.488 | INFO     | recorders.recorders:run_record:162 - [Afreeca][jeehyeoun] Started recording: [2024.08.10 00.12.45][Afreeca][jeehyeoun]새벽반은 지삐랑...♥♥♥.ts
2024-08-10 00:12:45.504 | INFO     | recorders.recorders:stream_writer:174 - [Afreeca][jeehyeoun] Obtained live stream link: [2024.08.10 00.12.45][Afreeca][jeehyeoun]새벽반은 지삐랑...♥♥♥.ts
https://pc-web.stream.afreecatv.com/live-stmc-22/auth_playlist.m3u8?aid=.A32.7bbT56vyHM9fKZk.xoWm6T_mheE7zjsc_D_e4jbEkktOhs1zDShpWrv6Ld_s1Y5WFEtwvXIpBfbDww08vpTbymSTzCNQLXA_sR3F8PCslTC0Fc9O0q6S07JnWi8
2024-08-10 00:12:50.839 | INFO     | recorders.recorders:stream_writer:180 - [Afreeca][jeehyeoun] Recording in progress: [2024.08.10 00.12.45][Afreeca][jeehyeoun]새벽반은 지삐랑...♥♥♥.ts