2024-07-18 14:03:39.162 | INFO     | utils.utils:info:59 - [TikTok][qiqiqiqi95] Cannot find Room ID.
2024-07-18 14:03:39.569 | INFO     | utils.utils:info:59 - [TikTok][qiqiqiqi95] room_id not found
2024-07-18 14:03:39.569 | INFO     | utils.utils:info:59 - Waiting 10 seconds
2024-07-18 14:03:49.952 | INFO     | utils.utils:info:59 - [TikTok][qiqiqiqi95] Cannot find Room ID.
2024-07-18 14:03:50.344 | INFO     | utils.utils:info:59 - [TikTok][qiqiqiqi95] room_id not found
2024-07-18 14:03:50.344 | INFO     | utils.utils:info:59 - Waiting 10 seconds
2024-07-18 14:04:43.635 | ERROR    | utils.utils:error:67 - [TikTok][qiqiqiqi95] Exception occurred: HTTPSConnectionPool(host='www.tiktok.com', port=443): Max retries exceeded with url: /@qiqiqiqi95 (Caused by SSLError(SSLError(1, '[SSL: TLSV1_ALERT_INTERNAL_ERROR] tlsv1 alert internal error (_ssl.c:1000)')))
--- Logging error in Loguru Handler #1 ---
Record was: {'elapsed': datetime.timedelta(days=4, seconds=38638, microseconds=950994), 'exception': None, 'extra': {}, 'file': (name='utils.py', path='utils\\utils.py'), 'function': 'error', 'level': (name='ERROR', no=40, icon='❌'), 'line': 67, 'message': "[TikTok][qiqiqiqi95] Exception occurred: HTTPSConnectionPool(host='www.tiktok.com', port=443): Max retries exceeded with url: /@qiqiqiqi95 (Caused by SSLError(SSLError(1, '[SSL: TLSV1_ALERT_INTERNAL_ERROR] tlsv1 alert internal error (_ssl.c:1000)')))", 'module': 'utils', 'name': 'utils.utils', 'process': (id=12788, name='MainProcess'), 'thread': (id=12792, name='MainThread'), 'time': datetime(2024, 7, 18, 14, 4, 43, 635480, tzinfo=datetime.timezone(datetime.timedelta(seconds=32400), '대한민국 표준시'))}
Traceback (most recent call last):
  File "urllib3\connectionpool.py", line 466, in _make_request
  File "urllib3\connectionpool.py", line 1095, in _validate_conn
  File "urllib3\connection.py", line 652, in connect
  File "urllib3\connection.py", line 805, in _ssl_wrap_socket_and_match_hostname
  File "urllib3\util\ssl_.py", line 465, in ssl_wrap_socket
  File "urllib3\util\ssl_.py", line 509, in _ssl_wrap_socket_impl
  File "ssl.py", line 455, in wrap_socket
  File "ssl.py", line 1042, in _create
  File "ssl.py", line 1320, in do_handshake
ssl.SSLError: [SSL: TLSV1_ALERT_INTERNAL_ERROR] tlsv1 alert internal error (_ssl.c:1000)

During handling of the above exception, another exception occurred:

Traceback (most recent call last):
  File "urllib3\connectionpool.py", line 789, in urlopen
  File "urllib3\connectionpool.py", line 490, in _make_request
urllib3.exceptions.SSLError: [SSL: TLSV1_ALERT_INTERNAL_ERROR] tlsv1 alert internal error (_ssl.c:1000)

The above exception was the direct cause of the following exception:

Traceback (most recent call last):
  File "requests\adapters.py", line 667, in send
  File "urllib3\connectionpool.py", line 843, in urlopen
  File "urllib3\util\retry.py", line 519, in increment
urllib3.exceptions.MaxRetryError: HTTPSConnectionPool(host='www.tiktok.com', port=443): Max retries exceeded with url: /@qiqiqiqi95 (Caused by SSLError(SSLError(1, '[SSL: TLSV1_ALERT_INTERNAL_ERROR] tlsv1 alert internal error (_ssl.c:1000)')))

During handling of the above exception, another exception occurred:

Traceback (most recent call last):
  File "recorders\recorders.py", line 318, in test_get_room_id_from_user
  File "requests\api.py", line 73, in get
  File "requests\api.py", line 59, in request
  File "requests\sessions.py", line 589, in request
  File "requests\sessions.py", line 703, in send
  File "requests\adapters.py", line 698, in send
requests.exceptions.SSLError: HTTPSConnectionPool(host='www.tiktok.com', port=443): Max retries exceeded with url: /@qiqiqiqi95 (Caused by SSLError(SSLError(1, '[SSL: TLSV1_ALERT_INTERNAL_ERROR] tlsv1 alert internal error (_ssl.c:1000)')))

During handling of the above exception, another exception occurred:

Traceback (most recent call last):
  File "loguru\_handler.py", line 206, in emit
  File "loguru\_file_sink.py", line 204, in write
  File "loguru\_file_sink.py", line 290, in _terminate_file
  File "loguru\_file_sink.py", line 84, in retention_age
PermissionError: [WinError 32] 다른 프로세스가 파일을 사용 중이기 때문에 프로세스가 액세스 할 수 없습니다: 'logs\\log_2024-07-14.log'
--- End of logging error ---
2024-07-18 14:04:43.666 | ERROR    | utils.utils:error:67 - Exception caught in main:
2024-07-18 14:04:43.666 | ERROR    | utils.utils:error:67 - HTTPSConnectionPool(host='www.tiktok.com', port=443): Max retries exceeded with url: /@qiqiqiqi95 (Caused by SSLError(SSLError(1, '[SSL: TLSV1_ALERT_INTERNAL_ERROR] tlsv1 alert internal error (_ssl.c:1000)')))

Traceback (most recent call last):
  File "urllib3\connectionpool.py", line 466, in _make_request
  File "urllib3\connectionpool.py", line 1095, in _validate_conn
  File "urllib3\connection.py", line 652, in connect
  File "urllib3\connection.py", line 805, in _ssl_wrap_socket_and_match_hostname
  File "urllib3\util\ssl_.py", line 465, in ssl_wrap_socket
  File "urllib3\util\ssl_.py", line 509, in _ssl_wrap_socket_impl
  File "ssl.py", line 455, in wrap_socket
  File "ssl.py", line 1042, in _create
  File "ssl.py", line 1320, in do_handshake
ssl.SSLError: [SSL: TLSV1_ALERT_INTERNAL_ERROR] tlsv1 alert internal error (_ssl.c:1000)

During handling of the above exception, another exception occurred:

Traceback (most recent call last):
  File "urllib3\connectionpool.py", line 789, in urlopen
  File "urllib3\connectionpool.py", line 490, in _make_request
urllib3.exceptions.SSLError: [SSL: TLSV1_ALERT_INTERNAL_ERROR] tlsv1 alert internal error (_ssl.c:1000)

The above exception was the direct cause of the following exception:

Traceback (most recent call last):
  File "requests\adapters.py", line 667, in send
  File "urllib3\connectionpool.py", line 843, in urlopen
  File "urllib3\util\retry.py", line 519, in increment
urllib3.exceptions.MaxRetryError: HTTPSConnectionPool(host='www.tiktok.com', port=443): Max retries exceeded with url: /@qiqiqiqi95 (Caused by SSLError(SSLError(1, '[SSL: TLSV1_ALERT_INTERNAL_ERROR] tlsv1 alert internal error (_ssl.c:1000)')))

During handling of the above exception, another exception occurred:

Traceback (most recent call last):
  File "main.py", line 12, in main
  File "recorders\recorders.py", line 66, in run
  File "recorders\recorders.py", line 386, in test_get_room_id_from_user
  File "recorders\recorders.py", line 318, in test_get_room_id_from_user
  File "requests\api.py", line 73, in get
  File "requests\api.py", line 59, in request
  File "requests\sessions.py", line 589, in request
  File "requests\sessions.py", line 703, in send
  File "requests\adapters.py", line 698, in send
requests.exceptions.SSLError: HTTPSConnectionPool(host='www.tiktok.com', port=443): Max retries exceeded with url: /@qiqiqiqi95 (Caused by SSLError(SSLError(1, '[SSL: TLSV1_ALERT_INTERNAL_ERROR] tlsv1 alert internal error (_ssl.c:1000)')))
PS C:\Users\lunar\Desktop\Outputs\TikTokLiveRecorder>